Workbook

Sheet Ordenes
A1: BELNR_ID | B1: ItemCode | C1: Descripción del artículo | D1: Sec | E1: Fecha Inicio | F1: Cantidad Base | G1: Horas | H1: Maquina | I1: Planificado | J1: Proceso | K1: Horas Programadas | L1: Línea
A2: 3955 | B2: 2140150001 | C2: Archivador Plastificado Negro, Lomo Ancho, t/Oficio Layconsa Office | D2: =+_xlfn.XLOOKUP(B2,BD_Spec!$A$1:$A$20529,BD_Spec!$L$1:$L$20529) -> 1 | E2: 46113 | F2: =+VLOOKUP(B2,Tiempos!$A$1:$N$7479,3,FALSE) -> 3500 | G2: =+VLOOKUP(B2,Tiempos!$A$1:$N$7479,5,FALSE) -> 12 | H2: =+VLOOKUP(B2,Tiempos!$A$1:$N$7479,7,FALSE) -> AMAN02 | I2: =+VLOOKUP(A2,OP!$A$1:$I$27881,9,FALSE) -> 30000 | J2: =(VLOOKUP(B2,BD_Spec!$A$1:$K$20517,6,FALSE)) -> Terminado | K2: 12 | L2: =+VLOOKUP(B2,BD_Spec!$A$1:$K$20517,7,FALSE) -> Manuales
A3: 3940 | B3: 2110080227 | C3: Bolígrafo Layconsa crystal L-036 Azul | D3: =+_xlfn.XLOOKUP(B3,BD_Spec!$A$1:$A$20529,BD_Spec!$L$1:$L$20529) -> 1 | E3: 46113 | F3: =+VLOOKUP(B3,Tiempos!$A$1:$N$7479,3,FALSE) -> 35000 | G3: =+VLOOKUP(B3,Tiempos!$A$1:$N$7479,5,FALSE) -> 12 | H3: =+VLOOKUP(B3,Tiempos!$A$1:$N$7479,7,FALSE) -> ENS03 | I3: =+VLOOKUP(A3,OP!$A$1:$I$27881,9,FALSE) -> 34000 | J3: =(VLOOKUP(B3,BD_Spec!$A$1:$K$20517,6,FALSE)) -> Terminado | K3: 12 | L3: =+VLOOKUP(B3,BD_Spec!$A$1:$K$20517,7,FALSE) -> Línea_036
A4: 3935 | B4: 2310040571 | C4: Formado Crayón Triangular Jumbo LYC Blanco | D4: =+_xlfn.XLOOKUP(B4,BD_Spec!$A$1:$A$20529,BD_Spec!$L$1:$L$20529) -> 9 | E4: 46118 | F4: =+VLOOKUP(B4,Tiempos!$A$1:$N$7479,3,FALSE) -> 25000 | G4: =+VLOOKUP(B4,Tiempos!$A$1:$N$7479,5,FALSE) -> 12 | H4: =+VLOOKUP(B4,Tiempos!$A$1:$N$7479,7,FALSE) -> FORM01 | I4: =+VLOOKUP(A4,OP!$A$1:$I$27881,9,FALSE) -> 5753 | J4: =(VLOOKUP(B4,BD_Spec!$A$1:$K$20517,6,FALSE)) -> Semiterminado | K4: 12 | L4: =+VLOOKUP(B4,BD_Spec!$A$1:$K$20517,7,FALSE) -> Crayones
A5: 3925 | B5: 2310040362 | C5: Formado Crayón Triangular Jumbo LYC Amarillo | D5: =+_xlfn.XLOOKUP(B5,BD_Spec!$A$1:$A$20529,BD_Spec!$L$1:$L$20529) -> 1 | E5: 46113 | F5: =+VLOOKUP(B5,Tiempos!$A$1:$N$7479,3,FALSE) -> 25000 | G5: =+VLOOKUP(B5,Tiempos!$A$1:$N$7479,5,FALSE) -> 12 | H5: =+VLOOKUP(B5,Tiempos!$A$1:$N$7479,7,FALSE) -> FORM01 | I5: =+VLOOKUP(A5,OP!$A$1:$I$27881,9,FALSE) -> 6410 | J5: =(VLOOKUP(B5,BD_Spec!$A$1:$K$20517,6,FALSE)) -> Semiterminado | K5: 12 | L5: =+VLOOKUP(B5,BD_Spec!$A$1:$K$20517,7,FALSE) -> Crayones
A6: 3926 | B6: 2310040364 | C6: Formado Crayón Triangular Jumbo LYC Anaranjado | D6: =+_xlfn.XLOOKUP(B6,BD_Spec!$A$1:$A$20529,BD_Spec!$L$1:$L$20529) -> 2 | E6: 46118 | F6: =+VLOOKUP(B6,Tiempos!$A$1:$N$7479,3,FALSE) -> 25000 | G6: =+VLOOKUP(B6,Tiempos!$A$1:$N$7479,5,FALSE) -> 12 | H6: =+VLOOKUP(B6,Tiempos!$A$1:$N$7479,7,FALSE) -> FORM01 | I6: =+VLOOKUP(A6,OP!$A$1:$I$27881,9,FALSE) -> 5855 | J6: =(VLOOKUP(B6,BD_Spec!$A$1:$K$20517,6,FALSE)) -> Semiterminado | K6: 12 | L6: =+VLOOKUP(B6,BD_Spec!$A$1:$K$20517,7,FALSE) -> Crayones
A7: 3933 | B7: 2310040371 | C7: Formado Crayón Triangular Jumbo LYC Rosado | D7: =+_xlfn.XLOOKUP(B7,BD_Spec!$A$1:$A$20529,BD_Spec!$L$1:$L$20529) -> 3 | E7: 46118 | F7: =+VLOOKUP(B7,Tiempos!$A$1:$N$7479,3,FALSE) -> 25000 | G7: =+VLOOKUP(B7,Tiempos!$A$1:$N$7479,5,FALSE) -> 12 | H7: =+VLOOKUP(B7,Tiempos!$A$1:$N$7479,7,FALSE) -> FORM01 | I7: =+VLOOKUP(A7,OP!$A$1:$I$27881,9,FALSE) -> 5889 | J7: =(VLOOKUP(B7,BD_Spec!$A$1:$K$20517,6,FALSE)) -> Semiterminado | K7: 12 | L7: =+VLOOKUP(B7,BD_Spec!$A$1:$K$20517,7,FALSE) -> Crayones
A8: 3924 | B8: 2310040361 | C8: Formado Crayón Triangular Jumbo LYC Rojo | D8: =+_xlfn.XLOOKUP(B8,BD_Spec!$A$1:$A$20529,BD_Spec!$L$1:$L$20529) -> 4 | E8: 46118 | F8: =+VLOOKUP(B8,Tiempos!$A$1:$N$7479,3,FALSE) -> 25000 | G8: =+VLOOKUP(B8,Tiempos!$A$1:$N$7479,5,FALSE) -> 12 | H8: =+VLOOKUP(B8,Tiempos!$A$1:$N$7479,7,FALSE) -> FORM01 | I8: =+VLOOKUP(A8,OP!$A$1:$I$27881,9,FALSE) -> 5882 | J8: =(VLOOKUP(B8,BD_Spec!$A$1:$K$20517,6,FALSE)) -> Semiterminado | K8: 12 | L8: =+VLOOKUP(B8,BD_Spec!$A$1:$K$20517,7,FALSE) -> Crayones
A9: 3929 | B9: 2310040367 | C9: Formado Crayón Triangular Jumbo LYC Celeste | D9: =+_xlfn.XLOOKUP(B9,BD_Spec!$A$1:$A$20529,BD_Spec!$L$1:$L$20529) -> 8 | E9: 46118 | F9: =+VLOOKUP(B9,Tiempos!$A$1:$N$7479,3,FALSE) -> 25000 | G9: =+VLOOKUP(B9,Tiempos!$A$1:$N$7479,5,FALSE) -> 12 | H9: =+VLOOKUP(B9,Tiempos!$A$1:$N$7479,7,FALSE) -> FORM01 | I9: =+VLOOKUP(A9,OP!$A$1:$I$27881,9,FALSE) -> 5882 | J9: =(VLOOKUP(B9,BD_Spec!$A$1:$K$20517,6,FALSE)) -> Semiterminado | K9: 12 | L9: =+VLOOKUP(B9,BD_Spec!$A$1:$K$20517,7,FALSE) -> Crayones
A10: 3930 | B10: 2310040368 | C10: Formado Crayón Triangular Jumbo LYC Azul | D10: =+_xlfn.XLOOKUP(B10,BD_Spec!$A$1:$A$20529,BD_Spec!$L$1:$L$20529) -> 7 | E10: 46118 | F10: =+VLOOKUP(B10,Tiempos!$A$1:$N$7479,3,FALSE) -> 25000 | G10: =+VLOOKUP(B10,Tiempos!$A$1:$N$7479,5,FALSE) -> 12 | H10: =+VLOOKUP(B10,Tiempos!$A$1:$N$7479,7,FALSE) -> FORM01 | I10: =+VLOOKUP(A10,OP!$A$1:$I$27881,9,FALSE) -> 5827 | J10: =(VLOOKUP(B10,BD_Spec!$A$1:$K$20517,6,FALSE)) -> Semiterminado | K10: 12 | L10: =+VLOOKUP(B10,BD_Spec!$A$1:$K$20517,7,FALSE) -> Crayones
A11: 3927 | B11: 2310040365 | C11: Formado Crayón Triangular Jumbo LYC Verde Claro | D11: =+_xlfn.XLOOKUP(B11,BD_Spec!$A$1:$A$20529,BD_Spec!$L$1:$L$20529) -> 5 | E11: 46118 | F11: =+VLOOKUP(B11,Tiempos!$A$1:$N$7479,3,FALSE) -> 25000 | G11: =+VLOOKUP(B11,Tiempos!$A$1:$N$7479,5,FALSE) -> 12 | H11: =+VLOOKUP(B11,Tiempos!$A$1:$N$7479,7,FALSE) -> FORM01 | I11: =+VLOOKUP(A11,OP!$A$1:$I$27881,9,FALSE) -> 5828 | J11: =(VLOOKUP(B11,BD_Spec!$A$1:$K$20517,6,FALSE)) -> Semiterminado | K11: 12 | L11: =+VLOOKUP(B11,BD_Spec!$A$1:$K$20517,7,FALSE) -> Crayones
A12: 3928 | B12: 2310040366 | C12: Formado Crayón Triangular Jumbo LYC Verde Oscuro | D12: =+_xlfn.XLOOKUP(B12,BD_Spec!$A$1:$A$20529,BD_Spec!$L$1:$L$20529) -> 6 | E12: 46118 | F12: =+VLOOKUP(B12,Tiempos!$A$1:$N$7479,3,FALSE) -> 25000 | G12: =+VLOOKUP(B12,Tiempos!$A$1:$N$7479,5,FALSE) -> 12 | H12: =+VLOOKUP(B12,Tiempos!$A$1:$N$7479,7,FALSE) -> FORM01 | I12: =+VLOOKUP(A12,OP!$A$1:$I$27881,9,FALSE) -> 5875 | J12: =(VLOOKUP(B12,BD_Spec!$A$1:$K$20517,6,FALSE)) -> Semiterminado | K12: 12 | L12: =+VLOOKUP(B12,BD_Spec!$A$1:$K$20517,7,FALSE) -> Crayones
A13: 3931 | B13: 2310040369 | C13: Formado Crayón Triangular Jumbo LYC Violeta | D13: =+_xlfn.XLOOKUP(B13,BD_Spec!$A$1:$A$20529,BD_Spec!$L$1:$L$20529) -> 10 | E13: 46118 | F13: =+VLOOKUP(B13,Tiempos!$A$1:$N$7479,3,FALSE) -> 25000 | G13: =+VLOOKUP(B13,Tiempos!$A$1:$N$7479,5,FALSE) -> 12 | H13: =+VLOOKUP(B13,Tiempos!$A$1:$N$7479,7,FALSE) -> FORM01 | I13: =+VLOOKUP(A13,OP!$A$1:$I$27881,9,FALSE) -> 5841 | J13: =(VLOOKUP(B13,BD_Spec!$A$1:$K$20517,6,FALSE)) -> Semiterminado | K13: 12 | L13: =+VLOOKUP(B13,BD_Spec!$A$1:$K$20517,7,FALSE) -> Crayones
... A29: 3862 | B29: 2310090441 | C29: Barril Para Plumón 045 - NP Negro | D29: =+_xlfn.XLOOKUP(B29,BD_Spec!$A$1:$A$20529,BD_Spec!$L$1:$L$20529) -> 12 | E29: 46118 | F29: =+VLOOKUP(B29,Tiempos!$A$1:$N$7479,3,FALSE) -> 98742.857 | G29: =+VLOOKUP(B29,Tiempos!$A$1:$N$7479,5,FALSE) -> 24 | H29: =+VLOOKUP(B29,Tiempos!$A$1:$N$7479,7,FALSE) -> INY05 | I29: =+VLOOKUP(A29,OP!$A$1:$I$27881,9,FALSE) -> 213000 | J29: =(VLOOKUP(B29,BD_Spec!$A$1:$K$20517,6,FALSE)) -> Inyección | K29: 24 | L29: =+VLOOKUP(B29,BD_Spec!$A$1:$K$20517,7,FALSE) -> Línea_045
A30: 3950 | B30: 2310160270 | C30: Tapa Para Témpera 30cc Sin Logo Color Blanco P.S. | D30: 1 | E30: 46118 | F30: =+VLOOKUP(B30,Tiempos!$A$1:$N$7479,3,FALSE) -> 63123.288 | G30: =+VLOOKUP(B30,Tiempos!$A$1:$N$7479,5,FALSE) -> 24 | H30: =+VLOOKUP(B30,Tiempos!$A$1:$N$7479,7,FALSE) -> INY06 | I30: 150000 | J30: =(VLOOKUP(B30,BD_Spec!$A$1:$K$20517,6,FALSE)) -> Inyección | K30: 24 | L30: =+VLOOKUP(B30,BD_Spec!$A$1:$K$20517,7,FALSE) -> Línea_Temp
A31: 3915 | B31: 2310160558 | C31: Tapa 30 cc P.S. | D31: =+_xlfn.XLOOKUP(B31,BD_Spec!$A$1:$A$20529,BD_Spec!$L$1:$L$20529) -> 1 | E31: 46132 | F31: =+VLOOKUP(B31,Tiempos!$A$1:$N$7479,3,FALSE) -> 38400 | G31: =+VLOOKUP(B31,Tiempos!$A$1:$N$7479,5,FALSE) -> 24 | H31: =+VLOOKUP(B31,Tiempos!$A$1:$N$7479,7,FALSE) -> INY08 | I31: =+VLOOKUP(A31,OP!$A$1:$I$27881,9,FALSE) -> 367000 | J31: =(VLOOKUP(B31,BD_Spec!$A$1:$K$20517,6,FALSE)) -> Inyección | K31: 24 | L31: =+VLOOKUP(B31,BD_Spec!$A$1:$K$20517,7,FALSE) -> Línea_Temp
A32: 3881 | B32: 2310160479 | C32: Tapa Para Plumón 045 - NP Piel | D32: =+_xlfn.XLOOKUP(B32,BD_Spec!$A$1:$A$20529,BD_Spec!$L$1:$L$20529) -> 1 | E32: 46118 | F32: =+VLOOKUP(B32,Tiempos!$A$1:$N$7479,3,FALSE) -> 96000 | G32: =+VLOOKUP(B32,Tiempos!$A$1:$N$7479,5,FALSE) -> 24 | H32: =+VLOOKUP(B32,Tiempos!$A$1:$N$7479,7,FALSE) -> INY09 | I32: =+VLOOKUP(A32,OP!$A$1:$I$27881,9,FALSE) -> 242000 | J32: =(VLOOKUP(B32,BD_Spec!$A$1:$K$20517,6,FALSE)) -> Inyección | K32: 24 | L32: =+VLOOKUP(B32,BD_Spec!$A$1:$K$20517,7,FALSE) -> Línea_045
A33: 3904 | B33: 2310160472 | C33: Tapa Para Plumón 045 - NP Amarillo | D33: =+_xlfn.XLOOKUP(B33,BD_Spec!$A$1:$A$20529,BD_Spec!$L$1:$L$20529) -> 2 | E33: 46118 | F33: =+VLOOKUP(B33,Tiempos!$A$1:$N$7479,3,FALSE) -> 96000 | G33: =+VLOOKUP(B33,Tiempos!$A$1:$N$7479,5,FALSE) -> 24 | H33: =+VLOOKUP(B33,Tiempos!$A$1:$N$7479,7,FALSE) -> INY09 | I33: =+VLOOKUP(A33,OP!$A$1:$I$27881,9,FALSE) -> 245000 | J33: =(VLOOKUP(B33,BD_Spec!$A$1:$K$20517,6,FALSE)) -> Inyección | K33: 24 | L33: =+VLOOKUP(B33,BD_Spec!$A$1:$K$20517,7,FALSE) -> Línea_045
A34: 3879 | B34: 2310160476 | C34: Tapa Para Plumón 045 - NP Anaranjado | D34: =+_xlfn.XLOOKUP(B34,BD_Spec!$A$1:$A$20529,BD_Spec!$L$1:$L$20529) -> 3 | E34: 46118 | F34: =+VLOOKUP(B34,Tiempos!$A$1:$N$7479,3,FALSE) -> 96000 | G34: =+VLOOKUP(B34,Tiempos!$A$1:$N$7479,5,FALSE) -> 24 | H34: =+VLOOKUP(B34,Tiempos!$A$1:$N$7479,7,FALSE) -> INY09 | I34: =+VLOOKUP(A34,OP!$A$1:$I$27881,9,FALSE) -> 243000 | J34: =(VLOOKUP(B34,BD_Spec!$A$1:$K$20517,6,FALSE)) -> Inyección | K34: 24 | L34: =+VLOOKUP(B34,BD_Spec!$A$1:$K$20517,7,FALSE) -> Línea_045
A35: 3878 | B35: 2310160475 | C35: Tapa Para Plumón 045 - NP Rosado | D35: =+_xlfn.XLOOKUP(B35,BD_Spec!$A$1:$A$20529,BD_Spec!$L$1:$L$20529) -> 4 | E35: 46118 | F35: =+VLOOKUP(B35,Tiempos!$A$1:$N$7479,3,FALSE) -> 96000 | G35: =+VLOOKUP(B35,Tiempos!$A$1:$N$7479,5,FALSE) -> 24 | H35: =+VLOOKUP(B35,Tiempos!$A$1:$N$7479,7,FALSE) -> INY09 | I35: =+VLOOKUP(A35,OP!$A$1:$I$27881,9,FALSE) -> 243000 | J35: =(VLOOKUP(B35,BD_Spec!$A$1:$K$20517,6,FALSE)) -> Inyección | K35: 24 | L35: =+VLOOKUP(B35,BD_Spec!$A$1:$K$20517,7,FALSE) -> Línea_045
A36: 3873 | B36: 2310160469 | C36: Tapa Para Plumón 045 - NP Rojo | D36: =+_xlfn.XLOOKUP(B36,BD_Spec!$A$1:$A$20529,BD_Spec!$L$1:$L$20529) -> 5 | E36: 46118 | F36: =+VLOOKUP(B36,Tiempos!$A$1:$N$7479,3,FALSE) -> 96000 | G36: =+VLOOKUP(B36,Tiempos!$A$1:$N$7479,5,FALSE) -> 24 | H36: =+VLOOKUP(B36,Tiempos!$A$1:$N$7479,7,FALSE) -> INY09 | I36: =+VLOOKUP(A36,OP!$A$1:$I$27881,9,FALSE) -> 231000 | J36: =(VLOOKUP(B36,BD_Spec!$A$1:$K$20517,6,FALSE)) -> Inyección | K36: 24 | L36: =+VLOOKUP(B36,BD_Spec!$A$1:$K$20517,7,FALSE) -> Línea_045
A37: 3880 | B37: 2310160477 | C37: Tapa Para Plumón 045 - NP Celeste | D37: =+_xlfn.XLOOKUP(B37,BD_Spec!$A$1:$A$20529,BD_Spec!$L$1:$L$20529) -> 6 | E37: 46118 | F37: =+VLOOKUP(B37,Tiempos!$A$1:$N$7479,3,FALSE) -> 96000 | G37: =+VLOOKUP(B37,Tiempos!$A$1:$N$7479,5,FALSE) -> 24 | H37: =+VLOOKUP(B37,Tiempos!$A$1:$N$7479,7,FALSE) -> INY09 | I37: =+VLOOKUP(A37,OP!$A$1:$I$27881,9,FALSE) -> 239000 | J37: =(VLOOKUP(B37,BD_Spec!$A$1:$K$20517,6,FALSE)) -> Inyección | K37: 24 | L37: =+VLOOKUP(B37,BD_Spec!$A$1:$K$20517,7,FALSE) -> Línea_045
A38: 3872 | B38: 2310160468 | C38: Tapa Para Plumón 045 - NP Azul | D38: =+_xlfn.XLOOKUP(B38,BD_Spec!$A$1:$A$20529,BD_Spec!$L$1:$L$20529) -> 7 | E38: 46118 | F38: =+VLOOKUP(B38,Tiempos!$A$1:$N$7479,3,FALSE) -> 96000 | G38: =+VLOOKUP(B38,Tiempos!$A$1:$N$7479,5,FALSE) -> 24 | H38: =+VLOOKUP(B38,Tiempos!$A$1:$N$7479,7,FALSE) -> INY09 | I38: =+VLOOKUP(A38,OP!$A$1:$I$27881,9,FALSE) -> 229000 | J38: =(VLOOKUP(B38,BD_Spec!$A$1:$K$20517,6,FALSE)) -> Inyección | K38: 24 | L38: =+VLOOKUP(B38,BD_Spec!$A$1:$K$20517,7,FALSE) -> Línea_045
A39: 3877 | B39: 2310160474 | C39: Tapa Para Plumón 045 - NP Verde Claro | D39: =+_xlfn.XLOOKUP(B39,BD_Spec!$A$1:$A$20529,BD_Spec!$L$1:$L$20529) -> 8 | E39: 46118 | F39: =+VLOOKUP(B39,Tiempos!$A$1:$N$7479,3,FALSE) -> 96000 | G39: =+VLOOKUP(B39,Tiempos!$A$1:$N$7479,5,FALSE) -> 24 | H39: =+VLOOKUP(B39,Tiempos!$A$1:$N$7479,7,FALSE) -> INY09 | I39: =+VLOOKUP(A39,OP!$A$1:$I$27881,9,FALSE) -> 244000 | J39: =(VLOOKUP(B39,BD_Spec!$A$1:$K$20517,6,FALSE)) -> Inyección | K39: 24 | L39: =+VLOOKUP(B39,BD_Spec!$A$1:$K$20517,7,FALSE) -> Línea_045
A40: 3875 | B40: 2310160471 | C40: Tapa Para Plumón 045 - NP Verde | D40: =+_xlfn.XLOOKUP(B40,BD_Spec!$A$1:$A$20529,BD_Spec!$L$1:$L$20529) -> 9 | E40: 46118 | F40: =+VLOOKUP(B40,Tiempos!$A$1:$N$7479,3,FALSE) -> 96000 | G40: =+VLOOKUP(B40,Tiempos!$A$1:$N$7479,5,FALSE) -> 24 | H40: =+VLOOKUP(B40,Tiempos!$A$1:$N$7479,7,FALSE) -> INY09 | I40: =+VLOOKUP(A40,OP!$A$1:$I$27881,9,FALSE) -> 242000 | J40: =(VLOOKUP(B40,BD_Spec!$A$1:$K$20517,6,FALSE)) -> Inyección | K40: 24 | L40: =+VLOOKUP(B40,BD_Spec!$A$1:$K$20517,7,FALSE) -> Línea_045
A41: 3882 | B41: 2310160500 | C41: Tapa Para Plumón 045 - NP Violeta | D41: =+_xlfn.XLOOKUP(B41,BD_Spec!$A$1:$A$20529,BD_Spec!$L$1:$L$20529) -> 10 | E41: 46118 | F41: =+VLOOKUP(B41,Tiempos!$A$1:$N$7479,3,FALSE) -> 96000 | G41: =+VLOOKUP(B41,Tiempos!$A$1:$N$7479,5,FALSE) -> 24 | H41: =+VLOOKUP(B41,Tiempos!$A$1:$N$7479,7,FALSE) -> INY09 | I41: =+VLOOKUP(A41,OP!$A$1:$I$27881,9,FALSE) -> 248000 | J41: =(VLOOKUP(B41,BD_Spec!$A$1:$K$20517,6,FALSE)) -> Inyección | K41: 24 | L41: =+VLOOKUP(B41,BD_Spec!$A$1:$K$20517,7,FALSE) -> Línea_045
A42: 3876 | B42: 2310160473 | C42: Tapa Para Plumón 045 - NP Marrón Oscuro | D42: =+_xlfn.XLOOKUP(B42,BD_Spec!$A$1:$A$20529,BD_Spec!$L$1:$L$20529) -> 11 | E42: 46118 | F42: =+VLOOKUP(B42,Tiempos!$A$1:$N$7479,3,FALSE) -> 96000 | G42: =+VLOOKUP(B42,Tiempos!$A$1:$N$7479,5,FALSE) -> 24 | H42: =+VLOOKUP(B42,Tiempos!$A$1:$N$7479,7,FALSE) -> INY09 | I42: =+VLOOKUP(A42,OP!$A$1:$I$27881,9,FALSE) -> 239000 | J42: =(VLOOKUP(B42,BD_Spec!$A$1:$K$20517,6,FALSE)) -> Inyección | K42: 24 | L42: =+VLOOKUP(B42,BD_Spec!$A$1:$K$20517,7,FALSE) -> Línea_045
... A60: 3911 | B60: 2310160264 | C60: Tapa Azul Para Tinta LT-4 P.S. | D60: =+_xlfn.XLOOKUP(B60,BD_Spec!$A$1:$A$20529,BD_Spec!$L$1:$L$20529) -> 1 | E60: 46139 | F60: =+VLOOKUP(B60,Tiempos!$A$1:$N$7479,3,FALSE) -> 14706.383 | G60: =+VLOOKUP(B60,Tiempos!$A$1:$N$7479,5,FALSE) -> 24 | H60: =+VLOOKUP(B60,Tiempos!$A$1:$N$7479,7,FALSE) -> INY15 | I60: =+VLOOKUP(A60,OP!$A$1:$I$27881,9,FALSE) -> 30000 | J60: =(VLOOKUP(B60,BD_Spec!$A$1:$K$20517,6,FALSE)) -> Inyección | K60: 24 | L60: =+VLOOKUP(B60,BD_Spec!$A$1:$K$20517,7,FALSE) -> Línea_126
A61: 3912 | B61: 2310160265 | C61: Tapa Negra Para Tinta LT-4 P.S. | D61: 2 | E61: 46118 | F61: =+VLOOKUP(B61,Tiempos!$A$1:$N$7479,3,FALSE) -> 14706.383 | G61: =+VLOOKUP(B61,Tiempos!$A$1:$N$7479,5,FALSE) -> 24 | H61: =+VLOOKUP(B61,Tiempos!$A$1:$N$7479,7,FALSE) -> INY15 | I61: =+VLOOKUP(A61,OP!$A$1:$I$27881,9,FALSE) -> 30000 | J61: =(VLOOKUP(B61,BD_Spec!$A$1:$K$20517,6,FALSE)) -> Inyección | K61: 24 | L61: =+VLOOKUP(B61,BD_Spec!$A$1:$K$20517,7,FALSE) -> Línea_126
A62: 3913 | B62: 2310160266 | C62: Tapa Roja Para Tinta LT-4 P.S. | D62: 3 | E62: 46118 | F62: =+VLOOKUP(B62,Tiempos!$A$1:$N$7479,3,FALSE) -> 14706.383 | G62: =+VLOOKUP(B62,Tiempos!$A$1:$N$7479,5,FALSE) -> 24 | H62: =+VLOOKUP(B62,Tiempos!$A$1:$N$7479,7,FALSE) -> INY15 | I62: =+VLOOKUP(A62,OP!$A$1:$I$27881,9,FALSE) -> 50000 | J62: =(VLOOKUP(B62,BD_Spec!$A$1:$K$20517,6,FALSE)) -> Inyección | K62: 24 | L62: =+VLOOKUP(B62,BD_Spec!$A$1:$K$20517,7,FALSE) -> Línea_126
A63: 3944 | B63: 2500120066 | C63: Frascos Transparente de 125cc Para Témpera P.S. | D63: 1 | E63: 46113 | F63: =+VLOOKUP(B63,Tiempos!$A$1:$N$7479,3,FALSE) -> 6545.4545 | G63: =+VLOOKUP(B63,Tiempos!$A$1:$N$7479,5,FALSE) -> 24 | H63: =+VLOOKUP(B63,Tiempos!$A$1:$N$7479,7,FALSE) -> SOP01 | I63: =+VLOOKUP(A63,OP!$A$1:$I$27881,9,FALSE) -> 62000 | J63: =(VLOOKUP(B63,BD_Spec!$A$1:$K$20517,6,FALSE)) -> Soplado | K63: 24 | L63: =+VLOOKUP(B63,BD_Spec!$A$1:$K$20517,7,FALSE) -> Línea_Temp
A64: 3907 | B64: 2310230056 | C64: Frasco 126 Plata Para Tinta | D64: 2 | E64: 46118 | F64: =+VLOOKUP(B64,Tiempos!$A$1:$N$7479,3,FALSE) -> 6400 | G64: =+VLOOKUP(B64,Tiempos!$A$1:$N$7479,5,FALSE) -> 24 | H64: =+VLOOKUP(B64,Tiempos!$A$1:$N$7479,7,FALSE) -> SOP01 | I64: =+VLOOKUP(A64,OP!$A$1:$I$27881,9,FALSE) -> 61000 | J64: =(VLOOKUP(B64,BD_Spec!$A$1:$K$20517,6,FALSE)) -> Soplado | K64: 24 | L64: =+VLOOKUP(B64,BD_Spec!$A$1:$K$20517,7,FALSE) -> Soplado
A65: 3938 | B65: 2310230012 | C65: Frasco Transparente de 250Gr Para Témpera P.S. | D65: =+_xlfn.XLOOKUP(B65,BD_Spec!$A$1:$A$20529,BD_Spec!$L$1:$L$20529) -> 1 | E65: 46113 | F65: =+VLOOKUP(B65,Tiempos!$A$1:$N$7479,3,FALSE) -> 13090.909 | G65: =+VLOOKUP(B65,Tiempos!$A$1:$N$7479,5,FALSE) -> 24 | H65: =+VLOOKUP(B65,Tiempos!$A$1:$N$7479,7,FALSE) -> SOP02 | I65: =+VLOOKUP(A65,OP!$A$1:$I$27881,9,FALSE) -> 20000 | J65: =(VLOOKUP(B65,BD_Spec!$A$1:$K$20517,6,FALSE)) -> Soplado | K65: 24 | L65: =+VLOOKUP(B65,BD_Spec!$A$1:$K$20517,7,FALSE) -> Línea_Temp
A66: 3921 | B66: 2310230030 | C66: Frasco Blanco Ovalado Para Cola Sintética con Aplicador 250Gr P.S. | D66: 2 | E66: 46118 | F66: =+VLOOKUP(B66,Tiempos!$A$1:$N$7479,3,FALSE) -> 13090.909 | G66: =+VLOOKUP(B66,Tiempos!$A$1:$N$7479,5,FALSE) -> 24 | H66: =+VLOOKUP(B66,Tiempos!$A$1:$N$7479,7,FALSE) -> SOP02 | I66: =+VLOOKUP(A66,OP!$A$1:$I$27881,9,FALSE) -> 252000 | J66: =(VLOOKUP(B66,BD_Spec!$A$1:$K$20517,6,FALSE)) -> Soplado | K66: 24 | L66: =+VLOOKUP(B66,BD_Spec!$A$1:$K$20517,7,FALSE) -> Línea_Cola
A67: 3983 | B67: 2110040047 | C67: Crayón triangular cj. cartón Layconsa Puppy Jumbo x 12 | D67: 1 | E67: 46121 | F67: =+VLOOKUP(B67,Tiempos!$A$1:$N$7479,3,FALSE) -> 4000 | G67: 12 | H67: =+VLOOKUP(B67,Tiempos!$A$1:$N$7479,7,FALSE) -> ENCJ03 | I67: =+VLOOKUP(A67,OP!$A$1:$I$27881,9,FALSE) -> 3000 | J67: =(VLOOKUP(B67,BD_Spec!$A$1:$K$20517,6,FALSE)) -> Terminado | K67: 24 | L67: =+VLOOKUP(B67,BD_Spec!$A$1:$K$20517,7,FALSE) -> Crayones
A68: 3986 | B68: 2310360001 | C68: Tubito Para Bolígrafo 036 | D68: 1 | E68: 46120 | F68: =+VLOOKUP(B68,Tiempos!$A$1:$N$7479,3,FALSE) -> 50000 | G68: =+VLOOKUP(B68,Tiempos!$A$1:$N$7479,5,FALSE) -> 12 | H68: =+VLOOKUP(B68,Tiempos!$A$1:$N$7479,7,FALSE) -> EXT01 | I68: =+VLOOKUP(A68,OP!$A$1:$I$27881,9,FALSE) -> 330000 | J68: Semiterminado | K68: 24 | L68: =+VLOOKUP(B68,BD_Spec!$A$1:$K$20517,7,FALSE) -> Línea_036

Sheet BD_Spec
A1: Código_Material | B1: Descripción_Material | C1: Línea_PT | D1: Tipo_Material | E1: Familia_PT | F1: Proceso_Interno | G1: Líneas | H1: Subcomponente | I1: Sublìnea | J1: CONTAR.SI | K1: CV | L1: Secuencia | M1: Color | N1: Tipo_Material2 | Q1: A | R1: A | S1: A | T1: A
A2: 2310340006 | B2: Punta Carga 036F + Adaptador | C2: N/A | D2: Semiterminado | E2: N/A | F2: Semiterminado | G2: Bolígrafo 036 | H2: Colores | I2: Adaptador | J2: 1 | K2: 1 | L2: =IFERROR(_xlfn.XLOOKUP(A2,$Q$2:$Q$155,$T$2:$T$155),1) -> 1 | M2: =IFERROR(VLOOKUP(A2,$Q$2:$S$1310,3,FALSE),"N/A") -> N/A | N2: =IFERROR(VLOOKUP(A2,Materiales!$A$1:$G$5090,7,FALSE),F2) -> Semiterminado | Q2: 2310090469 | R2: Barril Para Marcador 042 - NP Piel P.S. | S2: Piel | T2: =+VLOOKUP(S2,$W$2:$X$13,2,FALSE) -> 1 | W2: Piel | X2: 1
A3: 2310340010 | B3: Punta Carga 036M + Adaptador | C3: N/A | D3: Semiterminado | E3: N/A | F3: Semiterminado | G3: Bolígrafo 036 | H3: Colores | I3: Adaptador | J3: 1 | K3: 1 | L3: =IFERROR(_xlfn.XLOOKUP(A3,$Q$2:$Q$155,$T$2:$T$155),1) -> 1 | M3: =IFERROR(VLOOKUP(A3,$Q$2:$S$1310,3,FALSE),"N/A") -> N/A | N3: =IFERROR(VLOOKUP(A3,Materiales!$A$1:$G$5090,7,FALSE),F3) -> Semiterminado | Q3: 2310090461 | R3: Barril Para Marcador 042 - NP Amarillo P.S. | S3: Amarillo | T3: =+VLOOKUP(S3,$W$2:$X$13,2,FALSE) -> 2 | W3: Amarillo | X3: 2
A4: 2320071180 | B4: Respaldo Boligrafo Layconsa 36 x 10 pz. | C4: N/A | D4: Imprenta | E4: N/A | F4: Semiterminado | G4: Bolígrafo 036 | H4: Colores | I4: Adaptador | J4: 1 | K4: 1 | L4: =IFERROR(_xlfn.XLOOKUP(A4,$Q$2:$Q$155,$T$2:$T$155),1) -> 1 | M4: =IFERROR(VLOOKUP(A4,$Q$2:$S$1310,3,FALSE),"N/A") -> N/A | N4: =IFERROR(VLOOKUP(A4,Materiales!$A$1:$G$5090,7,FALSE),F4) -> Semiterminado | Q4: 2310090466 | R4: Barril Para Marcador 042 - NP Anaranjado P.S. | S4: Anaranjado | T4: =+VLOOKUP(S4,$W$2:$X$13,2,FALSE) -> 3 | W4: Anaranjado | X4: 3
A5: 2320071173 | B5: Respaldo de Marcador 123x4 | C5: N/A | D5: Imprenta | E5: N/A | F5: Semiterminado | G5: Bolígrafo 036 | H5: Colores | I5: Adaptador | J5: 1 | K5: 1 | L5: =IFERROR(_xlfn.XLOOKUP(A5,$Q$2:$Q$155,$T$2:$T$155),1) -> 1 | M5: =IFERROR(VLOOKUP(A5,$Q$2:$S$1310,3,FALSE),"N/A") -> N/A | N5: =IFERROR(VLOOKUP(A5,Materiales!$A$1:$G$5090,7,FALSE),F5) -> Semiterminado | Q5: 2310090464 | R5: Barril Para Marcador 042 - NP Rosado P.S. | S5: Rosado | T5: =+VLOOKUP(S5,$W$2:$X$13,2,FALSE) -> 4 | W5: Rosado | X5: 4
A6: 2310320326 | B6: Homopolímero de Acetato de Vinilo PVA | C6: N/A | D6: Semiterminado | E6: N/A | F6: Masas y Tintas | G6: Masas y Tintas | H6: Cola | I6: Aditivos | J6: 1 | K6: 1 | L6: =IFERROR(_xlfn.XLOOKUP(A6,$Q$2:$Q$155,$T$2:$T$155),1) -> 1 | M6: =IFERROR(VLOOKUP(A6,$Q$2:$S$1310,3,FALSE),"N/A") -> N/A | N6: =IFERROR(VLOOKUP(A6,Materiales!$A$1:$G$5090,7,FALSE),F6) -> Masas y Tintas | Q6: 2310090459 | R6: Barril Para Marcador 042 - NP Rojo P.S. | S6: Rojo | T6: =+VLOOKUP(S6,$W$2:$X$13,2,FALSE) -> 5 | W6: Rojo | X6: 5
A7: 2310030273 | B7: Látex Vinil Acrílico al 55% Témperas | C7: N/A | D7: Semiterminado | E7: N/A | F7: Masas y Tintas | G7: Masas y Tintas | H7: Masa_Temp | I7: Aditivos | J7: 1 | K7: 1 | L7: =IFERROR(_xlfn.XLOOKUP(A7,$Q$2:$Q$155,$T$2:$T$155),1) -> 1 | M7: =IFERROR(VLOOKUP(A7,$Q$2:$S$1310,3,FALSE),"N/A") -> N/A | N7: =IFERROR(VLOOKUP(A7,Materiales!$A$1:$G$5090,7,FALSE),F7) -> Masas y Tintas | Q7: 2310090465 | R7: Barril Para Marcador 042 - NP Morado P.S. | S7: Morado | T7: =+VLOOKUP(S7,$W$2:$X$13,2,FALSE) -> 10 | W7: Morado | X7: 10
A8: 2310180048 | B8: Intermedio T.A. - Marcador | C8: N/A | D8: Semiterminado | E8: N/A | F8: Masas y Tintas | G8: Masas y Tintas | H8: Marcadores | I8: Aditivos | J8: 1 | K8: 1 | L8: =IFERROR(_xlfn.XLOOKUP(A8,$Q$2:$Q$155,$T$2:$T$155),1) -> 1 | M8: =IFERROR(VLOOKUP(A8,$Q$2:$S$1310,3,FALSE),"N/A") -> N/A | N8: =IFERROR(VLOOKUP(A8,Materiales!$A$1:$G$5090,7,FALSE),F8) -> Masas y Tintas | Q8: 2310090463 | R8: Barril Para Marcador 042 - NP Celeste P.S. | S8: Celeste | T8: =+VLOOKUP(S8,$W$2:$X$13,2,FALSE) -> 6 | W8: Celeste | X8: 6
A9: 2310030236 | B9: Dispersión al Agua Azul Rojizo | C9: N/A | D9: Semiterminado | E9: N/A | F9: Masas y Tintas | G9: Masas y Tintas | H9: Masa_Temp | I9: Aditivos | J9: 1 | K9: 1 | L9: =IFERROR(_xlfn.XLOOKUP(A9,$Q$2:$Q$155,$T$2:$T$155),1) -> 1 | M9: =IFERROR(VLOOKUP(A9,$Q$2:$S$1310,3,FALSE),"N/A") -> N/A | N9: =IFERROR(VLOOKUP(A9,Materiales!$A$1:$G$5090,7,FALSE),F9) -> Masas y Tintas | Q9: 2310090457 | R9: Barril Para Marcador 042 - NP Azul P.S. | S9: Azul | T9: =+VLOOKUP(S9,$W$2:$X$13,2,FALSE) -> 7 | W9: Azul | X9: 7
A10: 2310320356 | B10: Terotex 110 P.S. | C10: N/A | D10: Semiterminado | E10: N/A | F10: Masas y Tintas | G10: Masas y Tintas | H10: Limpiatipo | I10: Aditivos | J10: 1 | K10: 1 | L10: =IFERROR(_xlfn.XLOOKUP(A10,$Q$2:$Q$155,$T$2:$T$155),1) -> 1 | M10: =IFERROR(VLOOKUP(A10,$Q$2:$S$1310,3,FALSE),"N/A") -> N/A | N10: =IFERROR(VLOOKUP(A10,Materiales!$A$1:$G$5090,7,FALSE),F10) -> Masas y Tintas | Q10: 2310090468 | R10: Barril Para Marcador 042 - NP Verde Claro P.S. | S10: Verde Claro | T10: =+VLOOKUP(S10,$W$2:$X$13,2,FALSE) -> 8 | W10: Verde Claro | X10: 8
A11: 2310030240 | B11: Dispersión al Agua Verde | C11: N/A | D11: Semiterminado | E11: N/A | F11: Masas y Tintas | G11: Masas y Tintas | H11: Masa_Temp | I11: Aditivos | J11: 1 | K11: 1 | L11: =IFERROR(_xlfn.XLOOKUP(A11,$Q$2:$Q$155,$T$2:$T$155),1) -> 1 | M11: =IFERROR(VLOOKUP(A11,$Q$2:$S$1310,3,FALSE),"N/A") -> N/A | N11: =IFERROR(VLOOKUP(A11,Materiales!$A$1:$G$5090,7,FALSE),F11) -> Masas y Tintas | Q11: 2310090460 | R11: Barril Para Marcador 042 - NP Verde P.S. | S11: Verde | T11: =+VLOOKUP(S11,$W$2:$X$13,2,FALSE) -> 9 | W11: Verde | X11: 9
A12: 2310040536 | B12: Base Molienda de Crayones Roja LYC P.S. | C12: N/A | D12: Semiterminado | E12: N/A | F12: Masas y Tintas | G12: Masas y Tintas | H12: Colores | I12: Base_crayones | J12: 1 | K12: 1 | L12: =IFERROR(_xlfn.XLOOKUP(A12,$Q$2:$Q$155,$T$2:$T$155),1) -> 1 | M12: =IFERROR(VLOOKUP(A12,$Q$2:$S$1310,3,FALSE),"N/A") -> N/A | N12: =IFERROR(VLOOKUP(A12,Materiales!$A$1:$G$5090,7,FALSE),F12) -> Masas y Tintas | Q12: 2310090462 | R12: Barril Para Marcador 042 - NP Marrón P.S. | S12: Marrón | T12: =+VLOOKUP(S12,$W$2:$X$13,2,FALSE) -> 11 | W12: Marrón | X12: 11
A13: 2310040541 | B13: Base Molienda de Crayones Amarilla LYC P.S. | C13: N/A | D13: Semiterminado | E13: N/A | F13: Masas y Tintas | G13: Masas y Tintas | H13: Colores | I13: Base_crayones | J13: 1 | K13: 1 | L13: =IFERROR(_xlfn.XLOOKUP(A13,$Q$2:$Q$155,$T$2:$T$155),1) -> 1 | M13: =IFERROR(VLOOKUP(A13,$Q$2:$S$1310,3,FALSE),"N/A") -> N/A | N13: =IFERROR(VLOOKUP(A13,Materiales!$A$1:$G$5090,7,FALSE),F13) -> Masas y Tintas | Q13: 2310090458 | R13: Barril Para Marcador 042 - NP Negro P.S. | S13: Negro | T13: =+VLOOKUP(S13,$W$2:$X$13,2,FALSE) -> 12 | W13: Negro | X13: 12
A14: 2310040543 | B14: Base Molienda de Crayones Naranja P.S. | C14: N/A | D14: Semiterminado | E14: N/A | F14: Masas y Tintas | G14: Masas y Tintas | H14: Colores | I14: Base_crayones | J14: 1 | K14: 1 | L14: =IFERROR(_xlfn.XLOOKUP(A14,$Q$2:$Q$155,$T$2:$T$155),1) -> 1 | M14: =IFERROR(VLOOKUP(A14,$Q$2:$S$1310,3,FALSE),"N/A") -> N/A | N14: =IFERROR(VLOOKUP(A14,Materiales!$A$1:$G$5090,7,FALSE),F14) -> Masas y Tintas | Q14: 2310160355 | R14: Tapa Para Marcador 042 - N Piel P.S. | S14: Piel | T14: =+VLOOKUP(S14,$W$2:$X$13,2,FALSE) -> 1
A15: 2310040538 | B15: Base Molienda de Crayones Verde Claro LYC P.S. | C15: N/A | D15: Semiterminado | E15: N/A | F15: Masas y Tintas | G15: Masas y Tintas | H15: Colores | I15: Base_crayones | J15: 1 | K15: 1 | L15: =IFERROR(_xlfn.XLOOKUP(A15,$Q$2:$Q$155,$T$2:$T$155),1) -> 1 | M15: =IFERROR(VLOOKUP(A15,$Q$2:$S$1310,3,FALSE),"N/A") -> N/A | N15: =IFERROR(VLOOKUP(A15,Materiales!$A$1:$G$5090,7,FALSE),F15) -> Masas y Tintas | Q15: 2310160242 | R15: Tapa Para Marcador 042 - N Amarillo P.S. | S15: Amarillo | T15: =+VLOOKUP(S15,$W$2:$X$13,2,FALSE) -> 2 | W15: Blanco | X15: 9
A16: 2310040537 | B16: Base Molienda de Crayones Verde Oscuro LYC P.S. | C16: N/A | D16: Semiterminado | E16: N/A | F16: Masas y Tintas | G16: Masas y Tintas | H16: Colores | I16: Base_crayones | J16: 1 | K16: 1 | L16: =IFERROR(_xlfn.XLOOKUP(A16,$Q$2:$Q$155,$T$2:$T$155),1) -> 1 | M16: =IFERROR(VLOOKUP(A16,$Q$2:$S$1310,3,FALSE),"N/A") -> N/A | N16: =IFERROR(VLOOKUP(A16,Materiales!$A$1:$G$5090,7,FALSE),F16) -> Masas y Tintas | Q16: 2310160247 | R16: Tapa Para Marcador 042 - N Anaranjado P.S. | S16: Anaranjado | T16: =+VLOOKUP(S16,$W$2:$X$13,2,FALSE) -> 3 | W16: Amarillo | X16: 1
A17: 2310040540 | B17: Base Molienda de Crayones Celeste LYC P.S. | C17: N/A | D17: Semiterminado | E17: N/A | F17: Masas y Tintas | G17: Masas y Tintas | H17: Colores | I17: Base_crayones | J17: 1 | K17: 1 | L17: =IFERROR(_xlfn.XLOOKUP(A17,$Q$2:$Q$155,$T$2:$T$155),1) -> 1 | M17: =IFERROR(VLOOKUP(A17,$Q$2:$S$1310,3,FALSE),"N/A") -> N/A | N17: =IFERROR(VLOOKUP(A17,Materiales!$A$1:$G$5090,7,FALSE),F17) -> Masas y Tintas | Q17: 2310160245 | R17: Tapa Para Marcador 042 - N Rosado P.S. | S17: Rosado | T17: =+VLOOKUP(S17,$W$2:$X$13,2,FALSE) -> 4 | W17: Anaranjado | X17: 2
A18: 2310040545 | B18: Base Molienda de Crayones Azul P.S. | C18: N/A | D18: Semiterminado | E18: N/A | F18: Masas y Tintas | G18: Masas y Tintas | H18: Colores | I18: Base_crayones | J18: 1 | K18: 1 | L18: =IFERROR(_xlfn.XLOOKUP(A18,$Q$2:$Q$155,$T$2:$T$155),1) -> 1 | M18: =IFERROR(VLOOKUP(A18,$Q$2:$S$1310,3,FALSE),"N/A") -> N/A | N18: =IFERROR(VLOOKUP(A18,Materiales!$A$1:$G$5090,7,FALSE),F18) -> Masas y Tintas | Q18: 2310160240 | R18: Tapa Para Marcador 042 - N Rojo P.S. | S18: Rojo | T18: =+VLOOKUP(S18,$W$2:$X$13,2,FALSE) -> 5 | W18: Rosado | X18: 3
A19: 2310040572 | B19: Base Molienda de Crayones Blanco P.S. | C19: N/A | D19: Semiterminado | E19: N/A | F19: Masas y Tintas | G19: Masas y Tintas | H19: Colores | I19: Base_crayones | J19: 1 | K19: 1 | L19: =IFERROR(_xlfn.XLOOKUP(A19,$Q$2:$Q$155,$T$2:$T$155),1) -> 1 | M19: =IFERROR(VLOOKUP(A19,$Q$2:$S$1310,3,FALSE),"N/A") -> N/A | N19: =IFERROR(VLOOKUP(A19,Materiales!$A$1:$G$5090,7,FALSE),F19) -> Masas y Tintas | Q19: 2310160246 | R19: Tapa Para Marcador 042 - N Morado P.S. | S19: Morado | T19: =+VLOOKUP(S19,$W$2:$X$13,2,FALSE) -> 10 | W19: Rojo | X19: 4
A20: 2310040539 | B20: Base Molienda de Crayones Violeta LYC P.S. | C20: N/A | D20: Semiterminado | E20: N/A | F20: Masas y Tintas | G20: Masas y Tintas | H20: Colores | I20: Base_crayones | J20: 1 | K20: 1 | L20: =IFERROR(_xlfn.XLOOKUP(A20,$Q$2:$Q$155,$T$2:$T$155),1) -> 1 | M20: =IFERROR(VLOOKUP(A20,$Q$2:$S$1310,3,FALSE),"N/A") -> N/A | N20: =IFERROR(VLOOKUP(A20,Materiales!$A$1:$G$5090,7,FALSE),F20) -> Masas y Tintas | Q20: 2310160244 | R20: Tapa Para Marcador 042 - N Celeste P.S. | S20: Celeste | T20: =+VLOOKUP(S20,$W$2:$X$13,2,FALSE) -> 6 | W20: Morado | X20: 10
A21: 2310040544 | B21: Base Molienda de Crayones Negro P.S. | C21: N/A | D21: Semiterminado | E21: N/A | F21: Masas y Tintas | G21: Masas y Tintas | H21: Colores | I21: Base_crayones | J21: 1 | K21: 1 | L21: =IFERROR(_xlfn.XLOOKUP(A21,$Q$2:$Q$155,$T$2:$T$155),1) -> 1 | M21: =IFERROR(VLOOKUP(A21,$Q$2:$S$1310,3,FALSE),"N/A") -> N/A | N21: =IFERROR(VLOOKUP(A21,Materiales!$A$1:$G$5090,7,FALSE),F21) -> Masas y Tintas | Q21: 2310160238 | R21: Tapa Para Marcador 042 - N Azul P.S. | S21: Azul | T21: =+VLOOKUP(S21,$W$2:$X$13,2,FALSE) -> 7 | W21: Celeste | X21: 8
A22: 2310040546 | B22: Base Molienda de Crayones Rosado P.S. | C22: N/A | D22: Semiterminado | E22: N/A | F22: Masas y Tintas | G22: Masas y Tintas | H22: Colores | I22: Base_crayones | J22: 1 | K22: 1 | L22: =IFERROR(_xlfn.XLOOKUP(A22,$Q$2:$Q$155,$T$2:$T$155),1) -> 1 | M22: =IFERROR(VLOOKUP(A22,$Q$2:$S$1310,3,FALSE),"N/A") -> N/A | N22: =IFERROR(VLOOKUP(A22,Materiales!$A$1:$G$5090,7,FALSE),F22) -> Masas y Tintas | Q22: 2310160356 | R22: Tapa Para Marcador 042 - N Verde Claro P.S. | S22: Verde Claro | T22: =+VLOOKUP(S22,$W$2:$X$13,2,FALSE) -> 8 | W22: Azul | X22: 7
A23: 2310040542 | B23: Base Molienda de Crayones Marrón P.S. | C23: N/A | D23: Semiterminado | E23: N/A | F23: Masas y Tintas | G23: Masas y Tintas | H23: Colores | I23: Base_crayones | J23: 1 | K23: 1 | L23: =IFERROR(_xlfn.XLOOKUP(A23,$Q$2:$Q$155,$T$2:$T$155),1) -> 1 | M23: =IFERROR(VLOOKUP(A23,$Q$2:$S$1310,3,FALSE),"N/A") -> N/A | N23: =IFERROR(VLOOKUP(A23,Materiales!$A$1:$G$5090,7,FALSE),F23) -> Masas y Tintas | Q23: 2310160241 | R23: Tapa Para Marcador 042 - N Verde P.S. | S23: Verde | T23: =+VLOOKUP(S23,$W$2:$X$13,2,FALSE) -> 9 | W23: Verde Claro | X23: 5
A24: 2310360001 | B24: Tubito Para Bolígrafo 036 | C24: N/A | D24: Semiterminado | E24: N/A | F24: Extrusión | G24: Línea_036 | H24: Tubo | I24: Bolígrafo | J24: 1 | K24: 1 | L24: =IFERROR(_xlfn.XLOOKUP(A24,$Q$2:$Q$155,$T$2:$T$155),1) -> 1 | M24: =IFERROR(VLOOKUP(A24,$Q$2:$S$1310,3,FALSE),"N/A") -> N/A | N24: =IFERROR(VLOOKUP(A24,Materiales!$A$1:$G$5090,7,FALSE),F24) -> Extrusión | Q24: 2310160243 | R24: Tapa Para Marcador 042 - N Marrón P.S. | S24: Marrón | T24: =+VLOOKUP(S24,$W$2:$X$13,2,FALSE) -> 11 | W24: Verde | X24: 6
A25: 2310160416 | B25: Tapa Para Bolígrafo 033 Rojo | C25: N/A | D25: Semiterminado | E25: N/A | F25: Inyección | G25: Línea_036 | H25: Tapa | I25: Bolígrafo | J25: 1 | K25: 1 | L25: =IFERROR(_xlfn.XLOOKUP(A25,$Q$2:$Q$155,$T$2:$T$155),1) -> 1 | M25: =IFERROR(VLOOKUP(A25,$Q$2:$S$1310,3,FALSE),"N/A") -> N/A | N25: =IFERROR(VLOOKUP(A25,Materiales!$A$1:$G$5090,7,FALSE),F25) -> Inyección | Q25: 2310160239 | R25: Tapa Para Marcador 042 - N Negro P.S. | S25: Negro | T25: =+VLOOKUP(S25,$W$2:$X$13,2,FALSE) -> 12 | W25: Marrón | X25: 11
A26: 2310160390 | B26: Tapa 036 Amarillo | C26: N/A | D26: Semiterminado | E26: N/A | F26: Inyección | G26: Línea_036 | H26: Tapa | I26: Bolígrafo | J26: 1 | K26: 1 | L26: =IFERROR(_xlfn.XLOOKUP(A26,$Q$2:$Q$155,$T$2:$T$155),1) -> 1 | M26: =IFERROR(VLOOKUP(A26,$Q$2:$S$1310,3,FALSE),"N/A") -> N/A | N26: =IFERROR(VLOOKUP(A26,Materiales!$A$1:$G$5090,7,FALSE),F26) -> Inyección | Q26: 2310160353 | R26: Tapita Para Marcador 042 - N Piel | S26: Piel | T26: =+VLOOKUP(S26,$W$2:$X$13,2,FALSE) -> 1 | W26: Negro | X26: 12
A27: 2310160396 | B27: Tapa 036 Marron | C27: N/A | D27: Semiterminado | E27: N/A | F27: Inyección | G27: Línea_036 | H27: Tapa | I27: Bolígrafo | J27: 1 | K27: 1 | L27: =IFERROR(_xlfn.XLOOKUP(A27,$Q$2:$Q$155,$T$2:$T$155),1) -> 1 | M27: =IFERROR(VLOOKUP(A27,$Q$2:$S$1310,3,FALSE),"N/A") -> N/A | N27: =IFERROR(VLOOKUP(A27,Materiales!$A$1:$G$5090,7,FALSE),F27) -> Inyección | Q27: 2310160252 | R27: Tapita Para Marcador 042 - N Amarillo | S27: Amarillo | T27: =+VLOOKUP(S27,$W$2:$X$13,2,FALSE) -> 2
A28: 2310160393 | B28: Tapa 036 Morado | C28: N/A | D28: Semiterminado | E28: N/A | F28: Inyección | G28: Línea_036 | H28: Tapa | I28: Bolígrafo | J28: 1 | K28: 1 | L28: =IFERROR(_xlfn.XLOOKUP(A28,$Q$2:$Q$155,$T$2:$T$155),1) -> 1 | M28: =IFERROR(VLOOKUP(A28,$Q$2:$S$1310,3,FALSE),"N/A") -> N/A | N28: =IFERROR(VLOOKUP(A28,Materiales!$A$1:$G$5090,7,FALSE),F28) -> Inyección | Q28: 2310160257 | R28: Tapita Para Marcador 042 - N Anaranjado | S28: Anaranjado | T28: =+VLOOKUP(S28,$W$2:$X$13,2,FALSE) -> 3
A29: 2310160391 | B29: Tapa 036 Naranja | C29: N/A | D29: Semiterminado | E29: N/A | F29: Inyección | G29: Línea_036 | H29: Tapa | I29: Bolígrafo | J29: 1 | K29: 1 | L29: =IFERROR(_xlfn.XLOOKUP(A29,$Q$2:$Q$155,$T$2:$T$155),1) -> 1 | M29: =IFERROR(VLOOKUP(A29,$Q$2:$S$1310,3,FALSE),"N/A") -> N/A | N29: =IFERROR(VLOOKUP(A29,Materiales!$A$1:$G$5090,7,FALSE),F29) -> Inyección | Q29: 2310160255 | R29: Tapita Para Marcador 042 - N Rosado | S29: Rosado | T29: =+VLOOKUP(S29,$W$2:$X$13,2,FALSE) -> 4
A30: 2310160392 | B30: Tapa 036 Rosado | C30: N/A | D30: Semiterminado | E30: N/A | F30: Inyección | G30: Línea_036 | H30: Tapa | I30: Bolígrafo | J30: 1 | K30: 1 | L30: =IFERROR(_xlfn.XLOOKUP(A30,$Q$2:$Q$155,$T$2:$T$155),1) -> 1 | M30: =IFERROR(VLOOKUP(A30,$Q$2:$S$1310,3,FALSE),"N/A") -> N/A | N30: =IFERROR(VLOOKUP(A30,Materiales!$A$1:$G$5090,7,FALSE),F30) -> Inyección | Q30: 2310160250 | R30: Tapita Para Marcador 042 - N Rojo | S30: Rojo | T30: =+VLOOKUP(S30,$W$2:$X$13,2,FALSE) -> 5
A31: 2310160394 | B31: Tapa 036 Turqueza | C31: N/A | D31: Semiterminado | E31: N/A | F31: Inyección | G31: Línea_036 | H31: Tapa | I31: Bolígrafo | J31: 1 | K31: 1 | L31: =IFERROR(_xlfn.XLOOKUP(A31,$Q$2:$Q$155,$T$2:$T$155),1) -> 1 | M31: =IFERROR(VLOOKUP(A31,$Q$2:$S$1310,3,FALSE),"N/A") -> N/A | N31: =IFERROR(VLOOKUP(A31,Materiales!$A$1:$G$5090,7,FALSE),F31) -> Inyección | Q31: 2310160256 | R31: Tapita Para Marcador 042 - N Morado | S31: Morado | T31: =+VLOOKUP(S31,$W$2:$X$13,2,FALSE) -> 10
A32: 2310160062 | B32: Tapa Para Bolígrafo 036 Azul | C32: N/A | D32: Semiterminado | E32: N/A | F32: Inyección | G32: Línea_036 | H32: Tapa | I32: Bolígrafo | J32: 1 | K32: 1 | L32: =IFERROR(_xlfn.XLOOKUP(A32,$Q$2:$Q$155,$T$2:$T$155),1) -> 1 | M32: =IFERROR(VLOOKUP(A32,$Q$2:$S$1310,3,FALSE),"N/A") -> N/A | N32: =IFERROR(VLOOKUP(A32,Materiales!$A$1:$G$5090,7,FALSE),F32) -> Inyección | Q32: 2310160254 | R32: Tapita Para Marcador 042 - N Celeste | S32: Celeste | T32: =+VLOOKUP(S32,$W$2:$X$13,2,FALSE) -> 6
A33: 2310160064 | B33: Tapa Para Bolígrafo 036 Negro | C33: N/A | D33: Semiterminado | E33: N/A | F33: Inyección | G33: Línea_036 | H33: Tapa | I33: Bolígrafo | J33: 1 | K33: 1 | L33: =IFERROR(_xlfn.XLOOKUP(A33,$Q$2:$Q$155,$T$2:$T$155),1) -> 1 | M33: =IFERROR(VLOOKUP(A33,$Q$2:$S$1310,3,FALSE),"N/A") -> N/A | N33: =IFERROR(VLOOKUP(A33,Materiales!$A$1:$G$5090,7,FALSE),F33) -> Inyección | Q33: 2310160248 | R33: Tapita Para Marcador 042 - N Azul | S33: Azul | T33: =+VLOOKUP(S33,$W$2:$X$13,2,FALSE) -> 7
A34: 2310160063 | B34: Tapa Para Bolígrafo 036 Rojo | C34: N/A | D34: Semiterminado | E34: N/A | F34: Inyección | G34: Línea_036 | H34: Tapa | I34: Bolígrafo | J34: 1 | K34: 1 | L34: =IFERROR(_xlfn.XLOOKUP(A34,$Q$2:$Q$155,$T$2:$T$155),1) -> 1 | M34: =IFERROR(VLOOKUP(A34,$Q$2:$S$1310,3,FALSE),"N/A") -> N/A | N34: =IFERROR(VLOOKUP(A34,Materiales!$A$1:$G$5090,7,FALSE),F34) -> Inyección | Q34: 2310160354 | R34: Tapita Para Marcador 042 - N Verde Claro | S34: Verde Claro | T34: =+VLOOKUP(S34,$W$2:$X$13,2,FALSE) -> 8
A35: 2310160417 | B35: Tapa Para Bolígrafo 036 Verde Claro | C35: N/A | D35: Semiterminado | E35: N/A | F35: Inyección | G35: Línea_036 | H35: Tapa | I35: Bolígrafo | J35: 1 | K35: 1 | L35: =IFERROR(_xlfn.XLOOKUP(A35,$Q$2:$Q$155,$T$2:$T$155),1) -> 1 | M35: =IFERROR(VLOOKUP(A35,$Q$2:$S$1310,3,FALSE),"N/A") -> N/A | N35: =IFERROR(VLOOKUP(A35,Materiales!$A$1:$G$5090,7,FALSE),F35) -> Inyección | Q35: 2310160251 | R35: Tapita Para Marcador 042 - N Verde | S35: Verde | T35: =+VLOOKUP(S35,$W$2:$X$13,2,FALSE) -> 9
A36: 2310160383 | B36: Tapita 036 Amarillo N | C36: N/A | D36: Semiterminado | E36: N/A | F36: Inyección | G36: Línea_036 | H36: Tapita | I36: Bolígrafo | J36: 1 | K36: 1 | L36: =IFERROR(_xlfn.XLOOKUP(A36,$Q$2:$Q$155,$T$2:$T$155),1) -> 1 | M36: =IFERROR(VLOOKUP(A36,$Q$2:$S$1310,3,FALSE),"N/A") -> N/A | N36: =IFERROR(VLOOKUP(A36,Materiales!$A$1:$G$5090,7,FALSE),F36) -> Inyección | Q36: 2310160253 | R36: Tapita Para Marcador 042 - N Marrón | S36: Marrón | T36: =+VLOOKUP(S36,$W$2:$X$13,2,FALSE) -> 11
A37: 2310160389 | B37: Tapita 036 Marron N | C37: N/A | D37: Semiterminado | E37: N/A | F37: Inyección | G37: Línea_036 | H37: Tapita | I37: Bolígrafo | J37: 1 | K37: 1 | L37: =IFERROR(_xlfn.XLOOKUP(A37,$Q$2:$Q$155,$T$2:$T$155),1) -> 1 | M37: =IFERROR(VLOOKUP(A37,$Q$2:$S$1310,3,FALSE),"N/A") -> N/A | N37: =IFERROR(VLOOKUP(A37,Materiales!$A$1:$G$5090,7,FALSE),F37) -> Inyección | Q37: 2310160249 | R37: Tapita Para Marcador 042 - N Negro | S37: Negro | T37: =+VLOOKUP(S37,$W$2:$X$13,2,FALSE) -> 12
A38: 2310160386 | B38: Tapita 036 Morado N | C38: N/A | D38: Semiterminado | E38: N/A | F38: Inyección | G38: Línea_036 | H38: Tapita | I38: Bolígrafo | J38: 1 | K38: 1 | L38: =IFERROR(_xlfn.XLOOKUP(A38,$Q$2:$Q$155,$T$2:$T$155),1) -> 1 | M38: =IFERROR(VLOOKUP(A38,$Q$2:$S$1310,3,FALSE),"N/A") -> N/A | N38: =IFERROR(VLOOKUP(A38,Materiales!$A$1:$G$5090,7,FALSE),F38) -> Inyección | Q38: 2310090502 | R38: Barril Para Marcador LYC Serigrafiado 047 - MK Piel Imp. Blanco | S38: Piel | T38: =+VLOOKUP(S38,$W$2:$X$13,2,FALSE) -> 1
... A131: 2310160379 | B131: Tapa Para Marcador 042 - N 123 Verde P.S. | C131: N/A | D131: Semiterminado | E131: N/A | F131: Inyección | G131: Línea_042 | H131: Tapa | I131: Colores | J131: 1 | K131: 1 | L131: =IFERROR(_xlfn.XLOOKUP(A131,$Q$2:$Q$155,$T$2:$T$155),1) -> 1 | M131: =IFERROR(VLOOKUP(A131,$Q$2:$S$1310,3,FALSE),"N/A") -> N/A | N131: =IFERROR(VLOOKUP(A131,Materiales!$A$1:$G$5090,7,FALSE),F131) -> Inyección | Q131: 2310210138 | R131: Plumones LYC School 45 Granel Piel NP P.S. | S131: Piel | T131: =+VLOOKUP(S131,$W$2:$X$13,2,FALSE) -> 1
A132: 2310160408 | B132: Tapita Para Marcador 042 (123) - N Rojo | C132: N/A | D132: Semiterminado | E132: N/A | F132: Inyección | G132: Línea_042 | H132: Tapita | I132: Colores | J132: 1 | K132: 1 | L132: =IFERROR(_xlfn.XLOOKUP(A132,$Q$2:$Q$155,$T$2:$T$155),1) -> 1 | M132: =IFERROR(VLOOKUP(A132,$Q$2:$S$1310,3,FALSE),"N/A") -> N/A | N132: =IFERROR(VLOOKUP(A132,Materiales!$A$1:$G$5090,7,FALSE),F132) -> Inyección | Q132: 2310040558 | R132: Formado Crayón Jumbo LYC Marrón | S132: Marrón | T132: =+VLOOKUP(S132,$W$15:$X$26,2,FALSE) -> 11
...

Sheet Tiempos
A1: Código Semi | B1: 0 | C1: Cantidad Base | D1: T.MO | E1: T.Maq | F1: Cant.Opr | G1: Maquina | H1: Tarifa Maquina | I1: Tarifa MO | J1: Proceso | K1: T.ciclo | L1: Cav. Oper | M1: Cav. Tot | N1: Componente
A2: 2110020095 | B2: Plumones Layconsa School 45 Estuche x 12 | C2: 8000 | D2: 72 | E2: 12 | F2: 6 | G2: ENCJ02 | H2: 259.0706 | I2: 9.02076 | J2: Encajado | K2: 0 | L2: 0 | M2: 0
A3: 2310210127 | B3: Plumones LYC School 45 Granel Azul NP P.S. | C3: 50000 | D3: 12 | E3: 12 | F3: 1 | G3: ENS02 | H3: 128.5658 | I3: 11.9658 | J3: Ensamble | K3: 0 | L3: 0 | M3: 0
A4: 2310210128 | B4: Plumones LYC School 45 Granel Negro NP P.S. | C4: 50000 | D4: 12 | E4: 12 | F4: 1 | G4: ENS02 | H4: 128.5658 | I4: 11.9658 | J4: Ensamble | K4: 0 | L4: 0 | M4: 0
A5: 2310210129 | B5: Plumones LYC School 45 Granel Rojo NP P.S. | C5: 50000 | D5: 12 | E5: 12 | F5: 1 | G5: ENS02 | H5: 128.5658 | I5: 11.9658 | J5: Ensamble | K5: 0 | L5: 0 | M5: 0
A6: 2310210130 | B6: Plumones LYC School 45 Granel Verde NP P.S. | C6: 50000 | D6: 12 | E6: 12 | F6: 1 | G6: ENS02 | H6: 128.5658 | I6: 11.9658 | J6: Ensamble | K6: 0 | L6: 0 | M6: 0
A7: 2310210131 | B7: Plumones LYC School 45 Granel Amarillo NP P.S. | C7: 50000 | D7: 12 | E7: 12 | F7: 1 | G7: ENS02 | H7: 128.5658 | I7: 11.9658 | J7: Ensamble | K7: 0 | L7: 0 | M7: 0
A8: 2310210132 | B8: Plumones LYC School 45 Granel Marrón NP P.S. | C8: 50000 | D8: 12 | E8: 12 | F8: 1 | G8: ENS02 | H8: 128.5658 | I8: 11.9658 | J8: Ensamble | K8: 0 | L8: 0 | M8: 0
A9: 2310210133 | B9: Plumones LYC School 45 Granel Anaranjado NP P.S. | C9: 50000 | D9: 12 | E9: 12 | F9: 1 | G9: ENS02 | H9: 128.5658 | I9: 11.9658 | J9: Ensamble | K9: 0 | L9: 0 | M9: 0
A10: 2310210134 | B10: Plumones LYC School 45 Granel Rosado NP P.S. | C10: 50000 | D10: 12 | E10: 12 | F10: 1 | G10: ENS02 | H10: 128.5658 | I10: 11.9658 | J10: Ensamble | K10: 0 | L10: 0 | M10: 0
A11: 2310210135 | B11: Plumones LYC School 45 Granel Violeta NP P.S. | C11: 50000 | D11: 12 | E11: 12 | F11: 1 | G11: ENS02 | H11: 128.5658 | I11: 11.9658 | J11: Ensamble | K11: 0 | L11: 0 | M11: 0
A12: 2310210136 | B12: Plumones LYC School 45 Granel Celeste NP P.S. | C12: 50000 | D12: 12 | E12: 12 | F12: 1 | G12: ENS02 | H12: 128.5658 | I12: 11.9658 | J12: Ensamble | K12: 0 | L12: 0 | M12: 0
A13: 2310210137 | B13: Plumones LYC School 45 Granel Verde Limon NP P.S. | C13: 50000 | D13: 12 | E13: 12 | F13: 1 | G13: ENS02 | H13: 128.5658 | I13: 11.9658 | J13: Ensamble | K13: 0 | L13: 0 | M13: 0
A14: 2310210138 | B14: Plumones LYC School 45 Granel Piel NP P.S. | C14: 50000 | D14: 12 | E14: 12 | F14: 1 | G14: ENS02 | H14: 128.5658 | I14: 11.9658 | J14: Ensamble | K14: 0 | L14: 0 | M14: 0
A15: 2310090439 | B15: Barril Para Plumón 045 - NP Azul | C15: 98742.857 | D15: 24 | E15: 24 | F15: 2 | G15: INY05 | H15: 37.8816 | I15: 9.82405 | J15: Inyección | K15: 24.5 | L15: 28 | M15: 32 | N15: Barril
A16: 2310160468 | B16: Tapa Para Plumón 045 - NP Azul | C16: 96000 | D16: 24 | E16: 24 | F16: 1 | G16: INY09 | H16: 7.1629 | I16: 9.64384 | J16: Inyección | K16: 21.6 | L16: 24 | M16: 24 | N16: Tapa
A17: 2310160480 | B17: Tapita Para Plumón 045 - NP Azul | C17: 86979.866 | D17: 24 | E17: 24 | F17: 1 | G17: INY13 | H17: 9.6456 | I17: 9.64384 | J17: Inyección | K17: 29.8 | L17: 30 | M17: 32 | N17: Tapita
A18: 2310180036 | B18: Tinta Plumón Lavable Azul P.S. | C18: 200 | D18: 4 | E18: 4 | F18: 1 | G18: AGIT01 | H18: 32.5465 | I18: 10.63879 | J18: MYT | K18: 0 | L18: 0 | M18: 0
A19: 2310090441 | B19: Barril Para Plumón 045 - NP Negro | C19: 98742.857 | D19: 24 | E19: 24 | F19: 2 | G19: INY05 | H19: 37.8816 | I19: 9.82405 | J19: Inyección | K19: 24.5 | L19: 28 | M19: 32 | N19: Barril
A20: 2310160470 | B20: Tapa Para Plumón 045 - NP Negro | C20: 96000 | D20: 24 | E20: 24 | F20: 1 | G20: INY09 | H20: 7.1629 | I20: 9.64384 | J20: Inyección | K20: 21.6 | L20: 24 | M20: 24 | N20: Tapa
A21: 2310160482 | B21: Tapita Para Plumón 045 - NP Negro | C21: 86979.866 | D21: 24 | E21: 24 | F21: 1 | G21: INY13 | H21: 9.6456 | I21: 9.64384 | J21: Inyección | K21: 29.8 | L21: 30 | M21: 32 | N21: Tapita
A22: 2310180042 | B22: Tinta Plumón Lavable Negro P.S. | C22: 200 | D22: 4 | E22: 4 | F22: 1 | G22: AGIT01 | H22: 32.5465 | I22: 10.63879 | J22: MYT | K22: 0 | L22: 0 | M22: 0
A23: 2310090440 | B23: Barril Para Plumón 045 - NPRojo | C23: 98742.857 | D23: 24 | E23: 24 | F23: 2 | G23: INY05 | H23: 37.8816 | I23: 9.82405 | J23: Inyección | K23: 24.5 | L23: 28 | M23: 32 | N23: Barril
A24: 2310160469 | B24: Tapa Para Plumón 045 - NP Rojo | C24: 96000 | D24: 24 | E24: 24 | F24: 1 | G24: INY09 | H24: 7.1629 | I24: 9.64384 | J24: Inyección | K24: 21.6 | L24: 24 | M24: 24 | N24: Tapa
A25: 2310160481 | B25: Tapita Para Plumón 045 - NP Rojo | C25: 86979.866 | D25: 24 | E25: 24 | F25: 1 | G25: INY13 | H25: 9.6456 | I25: 9.64384 | J25: Inyección | K25: 29.8 | L25: 30 | M25: 32 | N25: Tapita
A26: 2310180041 | B26: Tinta Plumón Lavable Rojo P.S. | C26: 200 | D26: 4 | E26: 4 | F26: 1 | G26: AGIT01 | H26: 32.5465 | I26: 10.63879 | J26: MYT | K26: 0 | L26: 0 | M26: 0
A27: 2310090442 | B27: Barril Para Plumón 045 - NP Verde | C27: 98742.857 | D27: 24 | E27: 24 | F27: 2 | G27: INY05 | H27: 37.8816 | I27: 9.82405 | J27: Inyección | K27: 24.5 | L27: 28 | M27: 32 | N27: Barril
A28: 2310160471 | B28: Tapa Para Plumón 045 - NP Verde | C28: 96000 | D28: 24 | E28: 24 | F28: 1 | G28: INY09 | H28: 7.1629 | I28: 9.64384 | J28: Inyección | K28: 21.6 | L28: 24 | M28: 24 | N28: Tapa
A29: 2310160483 | B29: Tapita Para Plumón 045 - NP Verde | C29: 86979.866 | D29: 24 | E29: 24 | F29: 1 | G29: INY13 | H29: 9.6456 | I29: 9.64384 | J29: Inyección | K29: 29.8 | L29: 30 | M29: 32 | N29: Tapita
A30: 2310180044 | B30: Tinta Plumón Lavable Verde P.S. | C30: 200 | D30: 4 | E30: 4 | F30: 1 | G30: AGIT01 | H30: 32.5465 | I30: 10.63879 | J30: MYT | K30: 0 | L30: 0 | M30: 0
A31: 2310090443 | B31: Barril Para Plumón 045 - NP Amarillo | C31: 98742.857 | D31: 24 | E31: 24 | F31: 2 | G31: INY05 | H31: 37.8816 | I31: 9.82405 | J31: Inyección | K31: 24.5 | L31: 28 | M31: 32 | N31: Barril
A32: 2310160472 | B32: Tapa Para Plumón 045 - NP Amarillo | C32: 96000 | D32: 24 | E32: 24 | F32: 1 | G32: INY09 | H32: 7.1629 | I32: 9.64384 | J32: Inyección | K32: 21.6 | L32: 24 | M32: 24 | N32: Tapa
A33: 2310160484 | B33: Tapita Para Plumón 045 - NP Amarillo | C33: 86979.866 | D33: 24 | E33: 24 | F33: 1 | G33: INY13 | H33: 9.6456 | I33: 9.64384 | J33: Inyección | K33: 29.8 | L33: 30 | M33: 32 | N33: Tapita
A34: 2310180035 | B34: Tinta Plumón Lavable Amarillo P.S. | C34: 200 | D34: 4 | E34: 4 | F34: 1 | G34: AGIT01 | H34: 32.5465 | I34: 10.63879 | J34: MYT | K34: 0 | L34: 0 | M34: 0
A35: 2310090444 | B35: Barril Para Plumón 045 - NP Marrón Oscuro | C35: 98742.857 | D35: 24 | E35: 24 | F35: 2 | G35: INY05 | H35: 37.8816 | I35: 9.82405 | J35: Inyección | K35: 24.5 | L35: 28 | M35: 32 | N35: Barril
A36: 2310160473 | B36: Tapa Para Plumón 045 - NP Marrón Oscuro | C36: 96000 | D36: 24 | E36: 24 | F36: 1 | G36: INY09 | H36: 7.1629 | I36: 9.64384 | J36: Inyección | K36: 21.6 | L36: 24 | M36: 24 | N36: Tapa
A37: 2310160485 | B37: Tapita Para Plumón 045 - NP Marrón Oscuro | C37: 86979.866 | D37: 24 | E37: 24 | F37: 1 | G37: INY13 | H37: 9.6456 | I37: 9.64384 | J37: Inyección | K37: 29.8 | L37: 30 | M37: 32 | N37: Tapita
A38: 2310180039 | B38: Tinta Plumón Lavable Marrón P.S. | C38: 200 | D38: 4 | E38: 4 | F38: 1 | G38: AGIT01 | H38: 32.5465 | I38: 10.63879 | J38: MYT | K38: 0 | L38: 0 | M38: 0
A39: 2310090447 | B39: Barril Para Plumón 045 - NP Anaranjado | C39: 98742.857 | D39: 24 | E39: 24 | F39: 2 | G39: INY05 | H39: 37.8816 | I39: 9.82405 | J39: Inyección | K39: 24.5 | L39: 28 | M39: 32 | N39: Barril
A40: 2310160476 | B40: Tapa Para Plumón 045 - NP Anaranjado | C40: 96000 | D40: 24 | E40: 24 | F40: 1 | G40: INY09 | H40: 7.1629 | I40: 9.64384 | J40: Inyección | K40: 21.6 | L40: 24 | M40: 24 | N40: Tapa
...

Sheet OP
A1: BELNR_ID | B1: ItemCode | C1: Descripción del artículo | D1: Estado | E1: TYP | F1: WhsCode | G1: NombreAlmacen | H1: Responsable | I1: CantidadOrden | J1: Entregado | K1: Cliente | L1: FechaDocumento | M1: Columna1 | N1: Buscar
A2: 3 | B2: 2310230097 | C2: Frasco Para Témperas 30 cc NP P.S. | D2: CERRADO | E2: ÚTILES_LIMA | F2: ALMA070 | G2: Almacén Producción Inyección | H2: ANGEL | I2: 402000 | J2: 402000 | K2: Frascos Para Témperas 30 cc NP P.S. | L2: 45845 | N2: =+VLOOKUP(A2,Ordenes!$A$1:$A$669,1,FALSE) -> #N/A
A3: 4 | B3: 2310090459 | C3: Barril Para Marcador 042 - NP Rojo P.S. | D3: CERRADO | E3: ÚTILES_LIMA | F3: ALMA070 | G3: Almacén Producción Inyección | H3: ANGEL | I3: 128083 | J3: 126900 | K3: Barril Para Marcador 042 - NP Rojo P.S. | L3: 45845 | N3: =+VLOOKUP(A3,Ordenes!$A$1:$A$669,1,FALSE) -> #N/A
A4: 5 | B4: 2310090457 | C4: Barril Para Marcador 042 - NP Azul P.S. | D4: CERRADO | E4: ÚTILES_LIMA | F4: ALMA070 | G4: Almacén Producción Inyección | H4: ANGEL | I4: 179861 | J4: 179861 | K4: Barril Para Marcador 042 - NP Azul P.S. | L4: 45845 | N4: =+VLOOKUP(A4,Ordenes!$A$1:$A$669,1,FALSE) -> #N/A
A5: 6 | B5: 2310090460 | C5: Barril Para Marcador 042 - NP Verde P.S. | D5: CERRADO | E5: ÚTILES_LIMA | F5: ALMA070 | G5: Almacén Producción Inyección | H5: ANGEL | I5: 193487 | J5: 193220 | K5: Barril Para Marcador 042 - NP Verde P.S. | L5: 45845 | N5: =+VLOOKUP(A5,Ordenes!$A$1:$A$669,1,FALSE) -> #N/A
A6: 7 | B6: 2310090448 | C6: Barril Para Plumón 045 - NP Celeste | D6: CERRADO | E6: ÚTILES_LIMA | F6: ALMA070 | G6: Almacén Producción Inyección | H6: ANGEL | I6: 196272 | J6: 196272 | K6: Barril Para Plumón 045 - NP Celeste | L6: 45845 | N6: =+VLOOKUP(A6,Ordenes!$A$1:$A$669,1,FALSE) -> #N/A
A7: 8 | B7: 2310090445 | C7: Barril Para Plumón 045 - NP Verde Claro | D7: CERRADO | E7: ÚTILES_LIMA | F7: ALMA070 | G7: Almacén Producción Inyección | H7: ANGEL | I7: 196272 | J7: 194800 | K7: Barril Para Plumón 045 - NP Verde Claro | L7: 45845 | N7: =+VLOOKUP(A7,Ordenes!$A$1:$A$669,1,FALSE) -> #N/A
A8: 9 | B8: 2310090442 | C8: Barril Para Plumón 045 - NP Verde | D8: CERRADO | E8: ÚTILES_LIMA | F8: ALMA070 | G8: Almacén Producción Inyección | H8: ANGEL | I8: 196272 | J8: 196800 | K8: Barril Para Plumón 045 - NP Verde | L8: 45845 | N8: =+VLOOKUP(A8,Ordenes!$A$1:$A$669,1,FALSE) -> #N/A
A9: 10 | B9: 2310230002 | C9: Frasco Para Témperas 30 cc P.S. | D9: CERRADO | E9: ÚTILES_LIMA | F9: ALMA070 | G9: Almacén Producción Inyección | H9: ANGEL | I9: 600606 | J9: 594000 | K9: Frascos Para Témperas P.S. | L9: 45845 | N9: =+VLOOKUP(A9,Ordenes!$A$1:$A$669,1,FALSE) -> #N/A
A10: 11 | B10: 2310160476 | C10: Tapa Para Plumón 045 - NP Anaranjado | D10: CERRADO | E10: ÚTILES_LIMA | F10: ALMA070 | G10: Almacén Producción Inyección | H10: ANGEL | I10: 212548 | J10: 212550 | K10: Tapa Para Plumón 045 - NP Anaranjado | L10: 45845 | N10: =+VLOOKUP(A10,Ordenes!$A$1:$A$669,1,FALSE) -> #N/A
A11: 12 | B11: 2310160469 | C11: Tapa Para Plumón 045 - NP Rojo | D11: CERRADO | E11: ÚTILES_LIMA | F11: ALMA070 | G11: Almacén Producción Inyección | H11: ANGEL | I11: 173736 | J11: 173736 | K11: Tapa Para Plumón 045 - NP Rojo | L11: 45845 | N11: =+VLOOKUP(A11,Ordenes!$A$1:$A$669,1,FALSE) -> #N/A
A12: 13 | B12: 2310160471 | C12: Tapa Para Plumón 045 - NP Verde | D12: CERRADO | E12: ÚTILES_LIMA | F12: ALMA070 | G12: Almacén Producción Inyección | H12: ANGEL | I12: 222000 | J12: 224000 | K12: Tapa Para Plumón 045 - NP Verde | L12: 45845 | N12: =+VLOOKUP(A12,Ordenes!$A$1:$A$669,1,FALSE) -> #N/A
A13: 14 | B13: 2310160539 | C13: Tapa Base Dosificador P/Cola Rojo paleta P.S. | D13: CERRADO | E13: ÚTILES_LIMA | F13: ALMA070 | G13: Almacén Producción Inyección | H13: ANGEL | I13: 225684 | J13: 0 | K13: Tapa Base Dosificador Rojo paleta P.S. | L13: 45845 | N13: =+VLOOKUP(A13,Ordenes!$A$1:$A$669,1,FALSE) -> #N/A
... A321: 462 | B321: 2140110657 | C321: Cuad. Grap. Ray. Sweet Layconsa 80 H | D321: CERRADO | E321: CUADERNOS_LIMA | F321: ALMA073 | G321: Almacén Producción Cuadernos | H321: BERNARDO | I321: 1500 | J321: 0 | K321: disponible | L321: 45870 | N321: =+VLOOKUP(A321,Ordenes!$A$1:$A$669,1,FALSE) -> #N/A
A322: 466 | D322: CERRADO | E322: CUADERNOS_LIMA | H322: SIN RESPONSABLE | I322: 0 | J322: 0 | K322: Cuad. Grap. Ray. Kawaii Layconsa 80 H. | L322: 45870 | N322: =+VLOOKUP(A322,Ordenes!$A$1:$A$669,1,FALSE) -> #N/A
A323: 467 | B323: 2140110658 | C323: Cuad. Grap. Ray. Mandalas Layconsa 80 H | D323: CERRADO | E323: CUADERNOS_LIMA | F323: ALMA073 | G323: Almacén Producción Cuadernos | H323: BERNARDO | I323: 4500 | J323: 4525 | K323: Cuad. Grap. Ray. Mandalas Layconsa 80 H | L323: 45870 | N323: =+VLOOKUP(A323,Ordenes!$A$1:$A$669,1,FALSE) -> #N/A
A324: 468 | B324: 2140110661 | C324: Cuad. Grap. Ray. Fast Racer Layconsa 80 H | D324: CERRADO | E324: CUADERNOS_LIMA | F324: ALMA073 | G324: Almacén Producción Cuadernos | H324: BERNARDO | I324: 10000 | J324: 10026 | K324: Cuad. Grap. Ray. Fast Racer Layconsa 80 H | L324: 45870 | N324: =+VLOOKUP(A324,Ordenes!$A$1:$A$669,1,FALSE) -> #N/A
A325: 470 | B325: 2140110613 | C325: Cuad. Grap. Cuadr. Princess Club Layconsa 80 H | D325: CERRADO | E325: CUADERNOS_LIMA | F325: ALMA073 | G325: Almacén Producción Cuadernos | H325: BERNARDO | I325: 59000 | J325: 59175 | K325: Cuad. Grap. Cuadr. Princess Club Layconsa 80 H | L325: 45870 | N325: =+VLOOKUP(A325,Ordenes!$A$1:$A$669,1,FALSE) -> #N/A
A326: 471 | B326: 2140110615 | C326: Cuad. Grap. Cuadr. Unicornios Layconsa 80 H | D326: CERRADO | E326: CUADERNOS_LIMA | F326: ALMA073 | G326: Almacén Producción Cuadernos | H326: BERNARDO | I326: 24500 | J326: 24525 | K326: Cuad. Grap. Cuadr. Unicornios Layconsa 80 H | L326: 45870 | N326: =+VLOOKUP(A326,Ordenes!$A$1:$A$669,1,FALSE) -> #N/A
A327: 472 | B327: 2310040547 | C327: Formado Crayón Jumbo LYC Rojo | D327: CERRADO | E327: ÚTILES_LIMA | F327: ALMA072 | G327: Almacén Producción Masas y Tintas | H327: MATIAS | I327: 25000 | J327: 18254 | K327: Formado Crayón Jumbo LYC Rojo | L327: 45873 | N327: =+VLOOKUP(A327,Ordenes!$A$1:$A$669,1,FALSE) -> #N/A
A328: 473 | B328: 2310040548 | C328: Formado Crayón Jumbo LYC Amarillo | D328: CERRADO | E328: ÚTILES_LIMA | F328: ALMA072 | G328: Almacén Producción Masas y Tintas | H328: MATIAS | I328: 25000 | J328: 29970 | K328: Formado Crayón Jumbo LYC Amarillo | L328: 45873 | N328: =+VLOOKUP(A328,Ordenes!$A$1:$A$669,1,FALSE) -> #N/A
A329: 474 | B329: 2310040549 | C329: Formado Crayón Jumbo LYC Blanco | D329: CERRADO | E329: ÚTILES_LIMA | F329: ALMA072 | G329: Almacén Producción Masas y Tintas | H329: MATIAS | I329: 25000 | J329: 26253 | K329: Formado Crayón Jumbo LYC Blanco | L329: 45873 | N329: =+VLOOKUP(A329,Ordenes!$A$1:$A$669,1,FALSE) -> #N/A
A330: 475 | B330: 2310040550 | C330: Formado Crayón Jumbo LYC Anaranjado | D330: CERRADO | E330: ÚTILES_LIMA | F330: ALMA072 | G330: Almacén Producción Masas y Tintas | H330: MATIAS | I330: 25000 | J330: 27114 | K330: Formado Crayón Jumbo LYC Anaranjado | L330: 45873 | N330: =+VLOOKUP(A330,Ordenes!$A$1:$A$669,1,FALSE) -> #N/A
A331: 476 | B331: 2310040551 | C331: Formado Crayón Jumbo LYC Verde Claro | D331: CERRADO | E331: ÚTILES_LIMA | F331: ALMA072 | G331: Almacén Producción Masas y Tintas | H331: MATIAS | I331: 25000 | J331: 27573 | K331: Formado Crayón Jumbo LYC Verde Claro | L331: 45873 | N331: =+VLOOKUP(A331,Ordenes!$A$1:$A$669,1,FALSE) -> #N/A
A332: 477 | B332: 2310040552 | C332: Formado Crayón Jumbo LYC Verde Oscuro | D332: CERRADO | E332: ÚTILES_LIMA | F332: ALMA072 | G332: Almacén Producción Masas y Tintas | H332: MATIAS | I332: 25000 | J332: 27133 | K332: Formado Crayón Jumbo LYC Verde Oscuro | L332: 45873 | N332: =+VLOOKUP(A332,Ordenes!$A$1:$A$669,1,FALSE) -> #N/A
A333: 478 | B333: 2310040553 | C333: Formado Crayón Jumbo LYC Celeste | D333: CERRADO | E333: ÚTILES_LIMA | F333: ALMA072 | G333: Almacén Producción Masas y Tintas | H333: MATIAS | I333: 25000 | J333: 26931 | K333: Formado Crayón Jumbo LYC Celeste | L333: 45873 | N333: =+VLOOKUP(A333,Ordenes!$A$1:$A$669,1,FALSE) -> #N/A
A334: 479 | B334: 2310040554 | C334: Formado Crayón Jumbo LYC Azul | D334: CERRADO | E334: ÚTILES_LIMA | F334: ALMA072 | G334: Almacén Producción Masas y Tintas | H334: MATIAS | I334: 25000 | J334: 27052 | K334: Formado Crayón Jumbo LYC Azul | L334: 45873 | N334: =+VLOOKUP(A334,Ordenes!$A$1:$A$669,1,FALSE) -> #N/A
... A1325: 1831 | B1325: 2310090491 | C1325: Barril Para Marcador LYC Serigrafiado 047 - MK Azul Imp. Blanco | D1325: CERRADO | E1325: ÚTILES_LIMA | F1325: ALMA071 | G1325: Almacén Producción Ensamble | H1325: ISAIAS | I1325: 20000 | J1325: 21420 | K1325: Barril Para Marcador LYC Serigrafiado 047 - MK Azul Imp. Blanco | L1325: 45957 | N1325: =+VLOOKUP(A1325,Ordenes!$A$1:$A$669,1,FALSE) -> #N/A
A1326: 1832 | D1326: CERRADO | E1326: CUADERNOS_LIMA | H1326: SIN RESPONSABLE | I1326: 0 | J1326: 0 | K1326: Cuad. Grap. 1x1 c/mco rojo 80 H. Layconsa Puppy | L1326: 45957 | N1326: =+VLOOKUP(A1326,Ordenes!$A$1:$A$669,1,FALSE) -> #N/A
A1327: 1833 | B1327: 2110210003 | C1327: Folder Layconsa A4 Cut Pets c/Fastener colores surtidos | D1327: CERRADO | E1327: ÚTILES_LIMA | F1327: ALMA071 | G1327: Almacén Producción Ensamble | H1327: ISAIAS | I1327: 4000 | J1327: 3988 | K1327: Folder Layconsa A4 Cut Pets c/Fastener colores surtidos | L1327: 45957 | N1327: =+VLOOKUP(A1327,Ordenes!$A$1:$A$669,1,FALSE) -> #N/A
A1328: 1834 | B1328: 2110210004 | C1328: Folder Layconsa A4 Kawaii c/Fastener colores surtidos | D1328: CERRADO | E1328: ÚTILES_LIMA | F1328: ALMA071 | G1328: Almacén Producción Ensamble | H1328: ISAIAS | I1328: 2500 | J1328: 2500 | K1328: Folder Layconsa A4 Kawaii c/Fastener colores surtidos | L1328: 45957 | N1328: =+VLOOKUP(A1328,Ordenes!$A$1:$A$669,1,FALSE) -> #N/A
A1329: 1835 | B1329: 2110210006 | C1329: Folder Layconsa A4 Unicorns c/Fastener colores surtidos | D1329: CERRADO | E1329: ÚTILES_LIMA | F1329: ALMA071 | G1329: Almacén Producción Ensamble | H1329: ISAIAS | I1329: 1500 | J1329: 1497 | K1329: Folder Layconsa A4 Unicorns c/Fastener colores surtidos | L1329: 45957 | N1329: =+VLOOKUP(A1329,Ordenes!$A$1:$A$669,1,FALSE) -> #N/A
A1330: 1836 | B1330: 2110210009 | C1330: Folder Layconsa A4 Pre-Escolar Niña c/Fastener colores surtidos | D1330: CERRADO | E1330: ÚTILES_LIMA | F1330: ALMA071 | G1330: Almacén Producción Ensamble | H1330: ISAIAS | I1330: 2000 | J1330: 1996 | K1330: Folder Layconsa A4 Pre-Escolar Niña c/Fastener colores surtidos | L1330: 45957 | N1330: =+VLOOKUP(A1330,Ordenes!$A$1:$A$669,1,FALSE) -> #N/A
A1331: 1837 | B1331: 2110210025 | C1331: Folder Layconsa A4 Femenino c/Fastener colores y diseños surtidos | D1331: CERRADO | E1331: ÚTILES_LIMA | F1331: ALMA071 | G1331: Almacén Producción Ensamble | H1331: ISAIAS | I1331: 4492 | J1331: 4492 | K1331: Folder Layconsa A4 Femenino c/Fastener colores y diseños surtidos | L1331: 45957 | N1331: =+VLOOKUP(A1331,Ordenes!$A$1:$A$669,1,FALSE) -> #N/A
A1332: 1838 | B1332: 2110210010 | C1332: Folder Layconsa Oficio Cut Pets c/Fastener colores surtidos | D1332: CERRADO | E1332: ÚTILES_LIMA | F1332: ALMA071 | G1332: Almacén Producción Ensamble | H1332: ISAIAS | I1332: 2000 | J1332: 1996 | K1332: Folder Layconsa Oficio Cut Pets c/Fastener colores surtidos | L1332: 45957 | N1332: =+VLOOKUP(A1332,Ordenes!$A$1:$A$669,1,FALSE) -> #N/A
A1333: 1839 | B1333: 2110210011 | C1333: Folder Layconsa Oficio Kawaii c/Fastener colores surtidos | D1333: CERRADO | E1333: ÚTILES_LIMA | F1333: ALMA071 | G1333: Almacén Producción Ensamble | H1333: ISAIAS | I1333: 3000 | J1333: 2989 | K1333: Folder Layconsa Oficio Kawaii c/Fastener colores surtidos | L1333: 45957 | N1333: =+VLOOKUP(A1333,Ordenes!$A$1:$A$669,1,FALSE) -> #N/A
A1334: 1840 | B1334: 2110210012 | C1334: Folder Layconsa Oficio Princess c/Fastener colores surtidos | D1334: CERRADO | E1334: ÚTILES_LIMA | F1334: ALMA071 | G1334: Almacén Producción Ensamble | H1334: ISAIAS | I1334: 1000 | J1334: 998 | K1334: Folder Layconsa Oficio Princess c/Fastener colores surtidos | L1334: 45957 | N1334: =+VLOOKUP(A1334,Ordenes!$A$1:$A$669,1,FALSE) -> #N/A
A1335: 1841 | B1335: 2110210013 | C1335: Folder Layconsa Oficio Unicorns c/Fastener colores surtidos | D1335: CERRADO | E1335: ÚTILES_LIMA | F1335: ALMA071 | G1335: Almacén Producción Ensamble | H1335: ISAIAS | I1335: 2000 | J1335: 1995 | K1335: Folder Layconsa Oficio Unicorns c/Fastener colores surtidos | L1335: 45957 | N1335: =+VLOOKUP(A1335,Ordenes!$A$1:$A$669,1,FALSE) -> #N/A
